[2024-07-19 13:22:15,557: ERROR: manager: No such comm target registered: jupyter.widget.control]
[2024-07-19 13:22:15,573: WARNING: base_comm: No such comm: 713b886f-5235-49ce-9829-2200e57360b0]
[2024-07-19 15:45:18,214: INFO: 3624453931: >>>>>> stage Data Ingestion stage started <<<<<<]
[2024-07-19 15:45:18,216: ERROR: 3624453931: name 'ConfigurationManager' is not defined]
Traceback (most recent call last):
  File "C:\Users\ADMIN\AppData\Local\Temp\ipykernel_13108\3624453931.py", line 22, in <module>
    obj.main()
  File "C:\Users\ADMIN\AppData\Local\Temp\ipykernel_13108\3624453931.py", line 9, in main
    config = ConfigurationManager()
             ^^^^^^^^^^^^^^^^^^^^
NameError: name 'ConfigurationManager' is not defined
[2024-07-19 15:46:01,740: INFO: 2255405276: >>>>>> stage Data Ingestion stage started <<<<<<]
[2024-07-19 15:46:01,742: ERROR: 2255405276: [Errno 2] No such file or directory: 'config\\config.yaml']
Traceback (most recent call last):
  File "C:\Users\ADMIN\AppData\Local\Temp\ipykernel_13108\2255405276.py", line 22, in <module>
    obj.main()
  File "C:\Users\ADMIN\AppData\Local\Temp\ipykernel_13108\2255405276.py", line 9, in main
    config = ConfigrationManager()
             ^^^^^^^^^^^^^^^^^^^^^
  File "C:\Users\ADMIN\AppData\Local\Temp\ipykernel_13108\3957926092.py", line 4, in __init__
    self.config = read_yaml(config_file_path)
                  ^^^^^^^^^^^^^^^^^^^^^^^^^^^
  File "D:\project\entbappy(Bappy Ahmed)\End-to-End-Chest-Cancer-Classification-using-MLflow-DVC\cancer\Lib\site-packages\ensure\main.py", line 872, in __call__
    return_val = self.f(*args, **kwargs)
                 ^^^^^^^^^^^^^^^^^^^^^^^
  File "C:\Users\ADMIN\AppData\Local\Temp\ipykernel_13108\1612917504.py", line 16, in read_yaml
    raise e
  File "C:\Users\ADMIN\AppData\Local\Temp\ipykernel_13108\1612917504.py", line 10, in read_yaml
    with open(file_path) as yaml_file:
         ^^^^^^^^^^^^^^^
  File "D:\project\entbappy(Bappy Ahmed)\End-to-End-Chest-Cancer-Classification-using-MLflow-DVC\cancer\Lib\site-packages\IPython\core\interactiveshell.py", line 324, in _modified_open
    return io_open(file, *args, **kwargs)
           ^^^^^^^^^^^^^^^^^^^^^^^^^^^^^^
FileNotFoundError: [Errno 2] No such file or directory: 'config\\config.yaml'
[2024-07-19 15:51:48,050: INFO: 2255405276: >>>>>> stage Data Ingestion stage started <<<<<<]
[2024-07-19 15:51:48,050: ERROR: 2255405276: [Errno 2] No such file or directory: 'config\\config.yaml']
Traceback (most recent call last):
  File "C:\Users\ADMIN\AppData\Local\Temp\ipykernel_11540\2255405276.py", line 22, in <module>
    obj.main()
  File "C:\Users\ADMIN\AppData\Local\Temp\ipykernel_11540\2255405276.py", line 9, in main
    config = ConfigrationManager()
             ^^^^^^^^^^^^^^^^^^^^^
  File "C:\Users\ADMIN\AppData\Local\Temp\ipykernel_11540\3957926092.py", line 4, in __init__
    self.config = read_yaml(config_file_path)
                  ^^^^^^^^^^^^^^^^^^^^^^^^^^^
  File "D:\project\entbappy(Bappy Ahmed)\End-to-End-Chest-Cancer-Classification-using-MLflow-DVC\cancer\Lib\site-packages\ensure\main.py", line 872, in __call__
    return_val = self.f(*args, **kwargs)
                 ^^^^^^^^^^^^^^^^^^^^^^^
  File "C:\Users\ADMIN\AppData\Local\Temp\ipykernel_11540\1612917504.py", line 16, in read_yaml
    raise e
  File "C:\Users\ADMIN\AppData\Local\Temp\ipykernel_11540\1612917504.py", line 10, in read_yaml
    with open(file_path) as yaml_file:
         ^^^^^^^^^^^^^^^
  File "D:\project\entbappy(Bappy Ahmed)\End-to-End-Chest-Cancer-Classification-using-MLflow-DVC\cancer\Lib\site-packages\IPython\core\interactiveshell.py", line 324, in _modified_open
    return io_open(file, *args, **kwargs)
           ^^^^^^^^^^^^^^^^^^^^^^^^^^^^^^
FileNotFoundError: [Errno 2] No such file or directory: 'config\\config.yaml'
[2024-07-19 15:56:51,744: INFO: 2255405276: >>>>>> stage Data Ingestion stage started <<<<<<]
[2024-07-19 15:56:51,755: ERROR: 2255405276: [Errno 2] No such file or directory: 'params.yaml']
Traceback (most recent call last):
  File "C:\Users\ADMIN\AppData\Local\Temp\ipykernel_16420\2255405276.py", line 22, in <module>
    obj.main()
  File "C:\Users\ADMIN\AppData\Local\Temp\ipykernel_16420\2255405276.py", line 9, in main
    config = ConfigrationManager()
             ^^^^^^^^^^^^^^^^^^^^^
  File "C:\Users\ADMIN\AppData\Local\Temp\ipykernel_16420\3957926092.py", line 5, in __init__
    self.params = read_yaml(params_file_path)
                  ^^^^^^^^^^^^^^^^^^^^^^^^^^^
  File "D:\project\entbappy(Bappy Ahmed)\End-to-End-Chest-Cancer-Classification-using-MLflow-DVC\cancer\Lib\site-packages\ensure\main.py", line 872, in __call__
    return_val = self.f(*args, **kwargs)
                 ^^^^^^^^^^^^^^^^^^^^^^^
  File "C:\Users\ADMIN\AppData\Local\Temp\ipykernel_16420\1612917504.py", line 16, in read_yaml
    raise e
  File "C:\Users\ADMIN\AppData\Local\Temp\ipykernel_16420\1612917504.py", line 10, in read_yaml
    with open(file_path) as yaml_file:
         ^^^^^^^^^^^^^^^
  File "D:\project\entbappy(Bappy Ahmed)\End-to-End-Chest-Cancer-Classification-using-MLflow-DVC\cancer\Lib\site-packages\IPython\core\interactiveshell.py", line 324, in _modified_open
    return io_open(file, *args, **kwargs)
           ^^^^^^^^^^^^^^^^^^^^^^^^^^^^^^
FileNotFoundError: [Errno 2] No such file or directory: 'params.yaml'
[2024-07-19 15:58:11,417: INFO: 2255405276: >>>>>> stage Data Ingestion stage started <<<<<<]
[2024-07-19 15:58:11,430: ERROR: 2255405276: yaml file is empty]
Traceback (most recent call last):
  File "C:\Users\ADMIN\AppData\Local\Temp\ipykernel_15296\1612917504.py", line 12, in read_yaml
    return ConfigBox(content)
           ^^^^^^^^^^^^^^^^^^
  File "box\\box.py", line 284, in box.box.Box.__init__
box.exceptions.BoxValueError: Cannot extrapolate Box from string

During handling of the above exception, another exception occurred:

Traceback (most recent call last):
  File "C:\Users\ADMIN\AppData\Local\Temp\ipykernel_15296\2255405276.py", line 22, in <module>
    obj.main()
  File "C:\Users\ADMIN\AppData\Local\Temp\ipykernel_15296\2255405276.py", line 9, in main
    config = ConfigrationManager()
             ^^^^^^^^^^^^^^^^^^^^^
  File "C:\Users\ADMIN\AppData\Local\Temp\ipykernel_15296\3957926092.py", line 5, in __init__
    self.params = read_yaml(params_file_path)
                  ^^^^^^^^^^^^^^^^^^^^^^^^^^^
  File "D:\project\entbappy(Bappy Ahmed)\End-to-End-Chest-Cancer-Classification-using-MLflow-DVC\cancer\Lib\site-packages\ensure\main.py", line 872, in __call__
    return_val = self.f(*args, **kwargs)
                 ^^^^^^^^^^^^^^^^^^^^^^^
  File "C:\Users\ADMIN\AppData\Local\Temp\ipykernel_15296\1612917504.py", line 14, in read_yaml
    raise ValueError("yaml file is empty")
ValueError: yaml file is empty
[2024-07-19 15:59:51,406: INFO: 2255405276: >>>>>> stage Data Ingestion stage started <<<<<<]
[2024-07-19 15:59:51,414: ERROR: 2255405276: yaml file is empty]
Traceback (most recent call last):
  File "C:\Users\ADMIN\AppData\Local\Temp\ipykernel_7592\1612917504.py", line 12, in read_yaml
    return ConfigBox(content)
           ^^^^^^^^^^^^^^^^^^
  File "box\\box.py", line 284, in box.box.Box.__init__
box.exceptions.BoxValueError: Cannot extrapolate Box from string

During handling of the above exception, another exception occurred:

Traceback (most recent call last):
  File "C:\Users\ADMIN\AppData\Local\Temp\ipykernel_7592\2255405276.py", line 22, in <module>
    obj.main()
  File "C:\Users\ADMIN\AppData\Local\Temp\ipykernel_7592\2255405276.py", line 9, in main
    config = ConfigrationManager()
             ^^^^^^^^^^^^^^^^^^^^^
  File "C:\Users\ADMIN\AppData\Local\Temp\ipykernel_7592\3957926092.py", line 5, in __init__
    self.params = read_yaml(params_file_path)
                  ^^^^^^^^^^^^^^^^^^^^^^^^^^^
  File "D:\project\entbappy(Bappy Ahmed)\End-to-End-Chest-Cancer-Classification-using-MLflow-DVC\cancer\Lib\site-packages\ensure\main.py", line 872, in __call__
    return_val = self.f(*args, **kwargs)
                 ^^^^^^^^^^^^^^^^^^^^^^^
  File "C:\Users\ADMIN\AppData\Local\Temp\ipykernel_7592\1612917504.py", line 14, in read_yaml
    raise ValueError("yaml file is empty")
ValueError: yaml file is empty
[2024-07-19 16:01:57,667: INFO: 2255405276: >>>>>> stage Data Ingestion stage started <<<<<<]
[2024-07-19 16:01:57,679: INFO: 1612917504: the file created at: artifacts]
[2024-07-19 16:01:57,683: ERROR: 2255405276: 'ConfigrationManager' object has no attribute 'get_data_ingestion_config']
Traceback (most recent call last):
  File "C:\Users\ADMIN\AppData\Local\Temp\ipykernel_8440\2255405276.py", line 22, in <module>
    obj.main()
  File "C:\Users\ADMIN\AppData\Local\Temp\ipykernel_8440\2255405276.py", line 10, in main
    data_ingestion_config = config.get_data_ingestion_config()
                            ^^^^^^^^^^^^^^^^^^^^^^^^^^^^^^^^
AttributeError: 'ConfigrationManager' object has no attribute 'get_data_ingestion_config'
[2024-07-19 16:02:54,905: INFO: 331079319: >>>>>> stage Data Ingestion stage started <<<<<<]
[2024-07-19 16:02:54,911: INFO: 1612917504: the file created at: artifacts]
[2024-07-19 16:02:54,916: ERROR: 331079319: "'ConfigBox' object has no attribute 'data_ingenstion'"]
Traceback (most recent call last):
  File "box\\box.py", line 592, in box.box.Box.__getitem__
KeyError: 'data_ingenstion'

The above exception was the direct cause of the following exception:

Traceback (most recent call last):
  File "box\\box.py", line 631, in box.box.Box.__getattr__
  File "box\\box.py", line 619, in box.box.Box.__getitem__
box.exceptions.BoxKeyError: "'data_ingenstion'"

During handling of the above exception, another exception occurred:

Traceback (most recent call last):
  File "box\\box.py", line 633, in box.box.Box.__getattr__
AttributeError: 'ConfigBox' object has no attribute 'data_ingenstion'

The above exception was the direct cause of the following exception:

Traceback (most recent call last):
  File "box\\config_box.py", line 29, in box.config_box.ConfigBox.__getattr__
  File "box\\box.py", line 647, in box.box.Box.__getattr__
box.exceptions.BoxKeyError: "'ConfigBox' object has no attribute 'data_ingenstion'"

During handling of the above exception, another exception occurred:

Traceback (most recent call last):
  File "box\\box.py", line 592, in box.box.Box.__getitem__
KeyError: 'data_ingenstion'

The above exception was the direct cause of the following exception:

Traceback (most recent call last):
  File "box\\box.py", line 631, in box.box.Box.__getattr__
  File "box\\box.py", line 619, in box.box.Box.__getitem__
box.exceptions.BoxKeyError: "'data_ingenstion'"

During handling of the above exception, another exception occurred:

Traceback (most recent call last):
  File "box\\box.py", line 633, in box.box.Box.__getattr__
AttributeError: 'ConfigBox' object has no attribute 'data_ingenstion'

The above exception was the direct cause of the following exception:

Traceback (most recent call last):
  File "C:\Users\ADMIN\AppData\Local\Temp\ipykernel_13116\331079319.py", line 22, in <module>
    obj.main()
  File "C:\Users\ADMIN\AppData\Local\Temp\ipykernel_13116\331079319.py", line 10, in main
    data_ingestion_config = config.get_data_ingenstion_config()
                            ^^^^^^^^^^^^^^^^^^^^^^^^^^^^^^^^^^^
  File "C:\Users\ADMIN\AppData\Local\Temp\ipykernel_13116\3957926092.py", line 10, in get_data_ingenstion_config
    config = self.config.data_ingenstion
             ^^^^^^^^^^^^^^^^^^^^^^^^^^^
  File "box\\config_box.py", line 31, in box.config_box.ConfigBox.__getattr__
  File "box\\box.py", line 647, in box.box.Box.__getattr__
box.exceptions.BoxKeyError: "'ConfigBox' object has no attribute 'data_ingenstion'"
[2024-07-19 16:07:12,595: INFO: 331079319: >>>>>> stage Data Ingestion stage started <<<<<<]
[2024-07-19 16:07:12,603: INFO: 1612917504: the file created at: artifacts]
[2024-07-19 16:07:12,603: INFO: 1612917504: the file created at: artifacts/data_ingestion]
[2024-07-19 16:07:12,608: ERROR: 331079319: DataIngestionConfigEntity.__init__() got an unexpected keyword argument 'local_dat_file']
Traceback (most recent call last):
  File "C:\Users\ADMIN\AppData\Local\Temp\ipykernel_13612\331079319.py", line 22, in <module>
    obj.main()
  File "C:\Users\ADMIN\AppData\Local\Temp\ipykernel_13612\331079319.py", line 10, in main
    data_ingestion_config = config.get_data_ingenstion_config()
                            ^^^^^^^^^^^^^^^^^^^^^^^^^^^^^^^^^^^
  File "C:\Users\ADMIN\AppData\Local\Temp\ipykernel_13612\968789176.py", line 13, in get_data_ingenstion_config
    data_enity = DataIngestionConfigEntity(root_dir=config.root_dir, source_URL=config.source_URL, local_dat_file=config.local_data_file, unzip_dir=config.unzip_dir)
                 ^^^^^^^^^^^^^^^^^^^^^^^^^^^^^^^^^^^^^^^^^^^^^^^^^^^^^^^^^^^^^^^^^^^^^^^^^^^^^^^^^^^^^^^^^^^^^^^^^^^^^^^^^^^^^^^^^^^^^^^^^^^^^^^^^^^^^^^^^^^^^^^^^^^^
TypeError: DataIngestionConfigEntity.__init__() got an unexpected keyword argument 'local_dat_file'
[2024-07-19 16:07:50,526: INFO: 331079319: >>>>>> stage Data Ingestion stage started <<<<<<]
[2024-07-19 16:07:50,540: INFO: 1612917504: the file created at: artifacts]
[2024-07-19 16:07:50,542: INFO: 1612917504: the file created at: artifacts/data_ingestion]
[2024-07-19 16:07:50,542: ERROR: 331079319: name 'data_entity' is not defined]
Traceback (most recent call last):
  File "C:\Users\ADMIN\AppData\Local\Temp\ipykernel_6816\331079319.py", line 22, in <module>
    obj.main()
  File "C:\Users\ADMIN\AppData\Local\Temp\ipykernel_6816\331079319.py", line 10, in main
    data_ingestion_config = config.get_data_ingenstion_config()
                            ^^^^^^^^^^^^^^^^^^^^^^^^^^^^^^^^^^^
  File "C:\Users\ADMIN\AppData\Local\Temp\ipykernel_6816\2095979475.py", line 15, in get_data_ingenstion_config
    return data_entity
           ^^^^^^^^^^^
NameError: name 'data_entity' is not defined
[2024-07-19 16:10:56,471: INFO: 331079319: >>>>>> stage Data Ingestion stage started <<<<<<]
[2024-07-19 16:10:56,481: INFO: 1612917504: the file created at: artifacts]
[2024-07-19 16:10:56,487: INFO: 1612917504: the file created at: artifacts/data_ingestion]
[2024-07-19 16:10:56,487: ERROR: 331079319: name 'DataIngestion' is not defined]
Traceback (most recent call last):
  File "C:\Users\ADMIN\AppData\Local\Temp\ipykernel_15556\331079319.py", line 22, in <module>
    obj.main()
  File "C:\Users\ADMIN\AppData\Local\Temp\ipykernel_15556\331079319.py", line 11, in main
    data_ingestion = DataIngestion(config=data_ingestion_config)
                     ^^^^^^^^^^^^^
NameError: name 'DataIngestion' is not defined
[2024-07-19 16:12:47,222: INFO: 331079319: >>>>>> stage Data Ingestion stage started <<<<<<]
[2024-07-19 16:12:47,236: INFO: 1612917504: the file created at: artifacts]
[2024-07-19 16:12:47,240: INFO: 1612917504: the file created at: artifacts/data_ingestion]
[2024-07-19 16:12:47,243: INFO: 664224474: Downloading data from https://drive.google.com/file/d/1z0mreUtRmR-P-magILsDR3T7M6IkGXtY/view?usp=sharing into file artifacts/data_ingestion/data.zip]
[2024-07-19 16:12:54,418: INFO: 664224474: Downloaded data from https://drive.google.com/file/d/1z0mreUtRmR-P-magILsDR3T7M6IkGXtY/view?usp=sharing into file artifacts/data_ingestion/data.zip]
[2024-07-19 16:12:55,559: INFO: 331079319: >>>>>> stage Data Ingestion stage completed <<<<<<

x==========x]
[2024-07-19 16:17:16,197: ERROR: manager: No such comm target registered: jupyter.widget.control]
[2024-07-19 16:17:16,205: WARNING: base_comm: No such comm: 582971c3-baf8-46fd-b604-bccb9e55db35]
